Workbook

Sheet Guide
B2: HATCHIN · UNIT ECONOMICS & FINANCIAL MODEL
B3: Live model · change any blue/yellow input and every tab recalculates · July 2026 prices
B5: HOW TO USE
B6: • Yellow/blue cells are inputs. Change them. Black cells are formulas. Green cells pull from another tab.
B7: • Start on Assumptions. Every driver lives there: token prices, usage, fees, tax, churn, conversion.
B8: • Basis & Method explains the method. Evidence Ledger gives the reason and confidence for every single claim.
B9: • Usage Windows is the cost cap (5-hour + weekly budget). B2C Personas and Company Sizes simulate real users.
B11: THE FIVE THINGS THAT MATTER
B12: 1. Chat is nearly free; autonomy (background AI work) is the only expensive thing. Meter autonomy, give chat away.
B13: 2. Pro gross margin ~80% (US/UK). India at ₹699 ~49%, and turns NEGATIVE below ~₹350/mo without a cap.
B14: 3. B2B is the profit engine: one ~15-seat account is worth ~23x a B2C Pro, with LTV:CAC of 11x to 22x.
B15: 4. Break-even is tiny: ~1 B2B account or ~12 US Pro subs covers base burn ($170/mo, or ₹14,620, at $0 draw).
... B23: Simulated advisory input, built from published frameworks, not the real people's review of Hatchin.

Sheet Basis & Method
B2: BASIS & METHOD · where every number comes from
B3: Read this if you want to know why the prices and costs are what they are. Nothing here is a guess without a stated reason.
B5: COST TO SERVE (what a user costs us)
B6: Built from the code's own COST_TABLE (DeepSeek $0.14/$0.28, Gemini $0.15/$0.60, Llama free) times an estimated
B7: token count. Chat is cheap because simple messages run on Meta's open-source Llama 3.3-70B, which costs about
B8: nothing per message (an open model you can self-host, or run on a free tier), and the rest run on DeepSeek Flash,
B9: the cheapest paid API, with the repeated prompt cached (~98% cheaper on input). Autonomy costs more because each
B10: background run reads and writes ~16,000 tokens across the task plus a peer review. So chat is genuinely near-free.
B12: PRICING (what we charge)
B13: US $19: sits $1 under the anchor every buyer already carries (ChatGPT Plus and Claude Pro are ~$20), so the story is
B14: 'one chatbot vs a 30-agent team.' UK £15: the clean charm point under £20, shown VAT-inclusive. India ₹699: set by
B15: purchasing power, not FX. FX would put $19 at ~₹1,634, which almost nobody in India pays for consumer software; ₹699
... B34: Simulated advisory input (council / psychology / partnerships) applies published frameworks to Hatchin, not the real people's review.

Sheet Evidence Ledger
A1: EVIDENCE LEDGER · every claim, the reason for it, and how sure we are
A2: Nothing here is made up. But the numbers are not all equal. FACT = published and checkable. MATH = calculated from those facts. ESTIMATE = my best guess where you have no real data yet, replace these first. SIMULATED = an informed opinion, not a real quote.
A4: Claim | B4: Why we say it (the reasoning) | C4: How sure | D4: How you can check it
A5: Chatting is almost free to run | B5: Simple messages (greetings, short) run on Meta's open-source Llama 3.3-70B, which costs about nothing (self-host, or a free tier). The rest run on DeepSeek Flash, the cheapest paid model, with the prompt cached (~98% cheaper), so about $0.0004 (₹0.03) a message. Even 900 messages a month is under $0.30 (₹26). | C5: MATH | D5: Your DeepSeek bill and Llama host, divided by messages sent.
A6: Background work costs ~$0.009 a task, on AVERAGE | B6: A typical task is about 16,000 tokens (~$0.009). But tasks vary a lot: a quick answer is ~5,000 tokens (~$0.003), a full document or deep research is 40,000+ (~$0.023 or more). So $0.009 is an average, which is why the cap is best set as a token budget, not a flat count of tasks. | C6: MATH | D6: Tokens per background run in your logs.
A7: A token is about three quarters of a word | B7: 1 million tokens is roughly 750,000 words, about 10 novels. In chat that is ~300 messages. $1 (₹86) of AI covers roughly 2,000 chat messages. This is how the tiny per-token prices turn into real usage. | C7: FACT | D7: Any tokenizer, or the provider's token counter.
A8: A paid user costs about $3.40 (₹292) a month | B8: Chat $0.45 + tasks $1.35 + card fee $0.85 + servers and support $0.75. | C8: MATH | D8: Add up your real monthly cost per active user.
A9: US profit is 81% | B9: You keep $18.15 of $19 after the card fee, and it costs $3.40 to serve. (18.15 minus 3.40) divided by 18.15. | C9: MATH | D9: Your Stripe payout minus your real cost.
A10: India profit is 49%, a loss below about ₹355 | B10: ₹699 minus 18% GST and the payment fee is about $6.70, minus the same $3.40 cost. | C10: MATH | D10: Confirm the GST rate and your Razorpay fee.
A11: One company is worth about 23 times a solo user | B11: A team pays far more, uses more, and stays far longer, so its lifetime value dwarfs a single Pro subscriber. | C11: MATH | D11: Compare account revenue and churn once you have real accounts.
A12: You break even at about 1 company or 12 solos | B12: Your fixed cost is about $170 a month; divide it by the profit each customer brings. | C12: MATH | D12: Your real monthly fixed cost.
A13: Cash lasts 147 months on $25k at no salary | B13: $25,000 divided by $170 a month of spend. | C13: MATH | D13: Your actual bank balance and monthly spend.
A14: The cap turns a heavy India user from a loss into a profit | B14: Uncapped they run about 1,500 tasks ($13.50); capped they run about 520 ($4.68), which stays under the price. | C14: MATH | D14: Set your own cap on the Usage Windows tab and read the row.
A15: About 3 in 100 free users will pay | B15: A careful, below-average guess. The typical figure is about 4.5 in 100. Yours could be higher or lower. | C15: ESTIMATE | D15: Watch your own signup-to-paid rate.
... A26: The advisor, psychology and partnership advice | B26: Well known marketing playbooks applied to Hatchin. Not real quotes or real opinions about your company. | C26: SIMULATED | D26: Treat as informed opinion, not fact.

Sheet Goals
A1: GOALS & MILESTONES · what we are aiming for, and why
A2: The plan turned into clear targets. Each ties to the growth forecast, and each has a reason.
A4: Goal | B4: Target | C4: When | D4: Why it matters
A5: Launch and get first users | B5: 100 signups | C5: Quarter 1 | D5: Prove people want it and seed the funnel.
A6: Become default-alive | B6: Cover $170/mo: 1 company or 12 paid | C6: Quarter 1 to 2 | D6: The business pays for itself, so there is no pressure to raise.
A7: Land the first companies | B7: 3 paying companies | C7: Quarter 2 to 3 | D7: Companies are the real engine, worth ~23x a solo user.
A8: Prove the growth loops | B8: ~$1,600/mo income | C8: Quarter 3 | D8: Shows referrals and partnerships actually work.
A9: Fix the leak | B9: Cut individual churn below 5%/mo | C9: Ongoing | D9: Individual retention is the weak spot; annual plans and onboarding fix it.
A10: Reach a real run-rate | B10: $10,750/mo, about $129k/yr | C10: Quarter 6 (18 months) | D10: A self-sustaining, fundable business.
A11: Be ready to raise (optional) | B11: Strong retention and growth | C11: After month 18 | D11: If you raise, do it from strength, not from need.

Sheet Assumptions
A1: ASSUMPTIONS · Hatchin Unit Economics
A2: Every yellow/blue cell is an editable input. Black = formula. Change inputs → whole model recalculates.
A3: LLM TOKEN PRICES ($ per 1M tokens)
A4: Parameter | B4: Value | C4: Unit | D4: Source / basis
A5: DeepSeek V4-Flash · input (cache-miss) | B5: 0.14 | C5: $/1M | D5: SRC · DeepSeek API, Jul-2026
A6: DeepSeek V4-Flash · input (cache-hit) | B6: 0.0028 | C6: $/1M | D6: SRC · ~98% cache discount
A7: DeepSeek V4-Flash · output | B7: 0.28 | C7: $/1M | D7: SRC
A8: DeepSeek V4-Pro · input (cache-miss) | B8: 0.435 | C8: $/1M | D8: SRC · promo-era
A9: DeepSeek V4-Pro · input (cache-hit) | B9: 0.003625 | C9: $/1M | D9: SRC
A10: DeepSeek V4-Pro · output | B10: 0.87 | C10: $/1M | D10: SRC
A11: Gemini 2.5-Flash · input | B11: 0.15 | C11: $/1M | D11: SRC · code COST_TABLE
A12: Gemini 2.5-Flash · output | B12: 0.6 | C12: $/1M | D12: SRC · code COST_TABLE
A13: Gemini 2.5-Pro · input | B13: 1.25 | C13: $/1M | D13: SRC · code COST_TABLE
A14: Gemini 2.5-Pro · output | B14: 5 | C14: $/1M | D14: SRC · code COST_TABLE
A15: Llama 3.3-70B (open source) · input | B15: 0 | C15: $/1M | D15: FREE · code books ₹0 (Groq free tier / self-host)
A16: Llama 3.3-70B (open source) · output | B16: 0 | C16: $/1M | D16: FREE · open-source Meta model
A18: TOKEN USAGE PROFILE (per interaction)
A19: Parameter | B19: Value | C19: Unit | D19: Source / basis
A20: Chat input · static prefix (cacheable) | B20: 1500 | C20: tokens | D20: EST · role identity + 14 rules
A21: Chat input · dynamic suffix | B21: 1000 | C21: tokens | D21: EST · history + user msg
A22: Chat output (visible + reasoning) | B22: 600 | C22: tokens | D22: EST
A23: Cache-hit rate (base) | B23: 0.5 | C23: % | D23: EST · 65-80% at scale improves margin
A24: Autonomy run · input (task+review) | B24: 12000 | C24: tokens | D24: EST
A25: Autonomy run · output (task+review) | B25: 4000 | C25: tokens | D25: EST
A27: PROVIDER MIX (share of traffic)
A28: Parameter | B28: Value | C28: Unit | D28: Source / basis
A29: Chat · DeepSeek Flash share | B29: 0.75 | C29: % | D29: EST · standard / complex messages
A30: Chat · Gemini Flash share | B30: 0.05 | C30: % | D30: EST · fallback
A31: Chat · Llama (open source, free) share | B31: 0.2 | C31: % | D31: EST · simple messages, ₹0
A32: Autonomy · DeepSeek Pro share | B32: 0.9 | C32: % | D32: EST
A33: Autonomy · Gemini Pro share | B33: 0.1 | C33: % | D33: EST · fallback
A35: REFERENCE · naive per-unit cost from list prices (computed)
A36: Parameter | B36: Value ($) | D36: Note
A37: DeepSeek Flash · per chat msg | B37: =($B$20*($B$23*$B$6+(1-$B$23)*$B$5)+$B$21*$B$5+$B$22*$B$7)/1000000 -> 0.0004151 | D37: Shown so you can see how the effective cost below was derived from raw token prices.
A38: Gemini Flash · per chat msg | B38: =(($B$20+$B$21)*$B$11+$B$22*$B$12)/1000000 -> 0.000735
A39: Llama (open source, free) · per chat msg | B39: =(($B$20+$B$21)*$B$15+$B$22*$B$16)/1000000 -> 0
A40: Blended · per chat msg (naive) | B40: =$B$29*B37+$B$30*B38+$B$31*B39 -> 0.000348075
A41: DeepSeek Pro · per autonomy run | B41: =($B$24*($B$23*$B$9+(1-$B$23)*$B$8)+$B$25*$B$10)/1000000 -> 0.00611175
A42: Gemini Pro · per autonomy run | B42: =($B$24*$B$13+$B$25*$B$14)/1000000 -> 0.035
A43: Blended · per autonomy run (naive) | B43: =$B$32*B41+$B$33*B42 -> 0.009000575
...

Sheet Cost to Serve
A1: COST TO SERVE ($ per user / month)
A2: Derived from Assumptions. Marginal = cash out the door per user. Fully-loaded = + allocated fixed & support.
A4: Line item | B4: Free | C4: Pro (B2C) | D4: B2B seat
A5: LLM · chat | B5: =Assumptions!$B$53*Assumptions!$B$47 -> 0.028 | C5: =Assumptions!$B$55*Assumptions!$B$48 -> 0.27 | D5: =Assumptions!$B$57*Assumptions!$B$48 -> 0.45
A6: LLM · autonomy | B6: =Assumptions!$B$54*Assumptions!$B$49 -> 0 | C6: =Assumptions!$B$56*Assumptions!$B$49 -> 1.35 | D6: =Assumptions!$B$58*Assumptions!$B$49 -> 2.7
A7: LLM subtotal | B7: =SUM(B5:B6) -> 0.028 | C7: =SUM(C5:C6) -> 1.62 | D7: =SUM(D5:D6) -> 3.15
A8: Payment fee (monthly bill) | B8: 0 | C8: ='B2C Pricing'!$B$5*Assumptions!$B$62+Assumptions!$B$63 -> 0.851 | D8: =Assumptions!$B$83 -> 0.9
A9: Variable infra | B9: =Assumptions!$B$74 -> 0.02 | C9: =Assumptions!$B$75 -> 0.1 | D9: =Assumptions!$B$76 -> 0.15
A10: MARGINAL subtotal | B10: =B7+B8+B9 -> 0.048 | C10: =C7+C8+C9 -> 2.571 | D10: =D7+D8+D9 -> 4.2
A11: Allocated fixed infra | B11: =Assumptions!$B$77 -> 0.03 | C11: =Assumptions!$B$78 -> 0.15 | D11: =Assumptions!$B$79 -> 0.2
A12: Support-time allocation | B12: =Assumptions!$B$80 -> 0.02 | C12: =Assumptions!$B$81 -> 0.5 | D12: =Assumptions!$B$82 -> 1.5
A13: FULLY-LOADED subtotal | B13: =B10+B11+B12 -> 0.098 | C13: =C10+C11+C12 -> 3.221 | D13: =D10+D11+D12 -> 5.9
A15: Heavy-user LLM ceiling (worst case) | B15: 5 | C15: 7 | D15: 11
A17: ONE BACKGROUND TASK: the $0.009 is an AVERAGE, tasks vary a lot
A18: Task type | B18: Tokens used | C18: Cost $ | D18: Cost ₹
A19: Light (quick answer, small lookup) | B19: 5000 | C19: =B19*Assumptions!$B$49/(Assumptions!$B$24+Assumptions!$B$25) -> 0.0028125 | D19: =C19*Assumptions!$B$69 -> 0.241875
A20: Typical / average (plan, short doc + review) | B20: 16000 | C20: =B20*Assumptions!$B$49/(Assumptions!$B$24+Assumptions!$B$25) -> 0.009 | D20: =C20*Assumptions!$B$69 -> 0.774
A21: Heavy (full document, deep research) | B21: 40000 | C21: =B21*Assumptions!$B$49/(Assumptions!$B$24+Assumptions!$B$25) -> 0.0225 | D21: =C21*Assumptions!$B$69 -> 1.935
A23: Because one task can cost 8x more than another, the cap is best run as a TOKEN budget (the way Claude does), not a flat count of tasks. Then the worst-case cost holds no matter the task mix. 'Tasks' is just the friendly way to explain it to users.
A25: WHAT A TOKEN IS (so the prices mean something)
A26: 1 token | B26: about 3/4 of a word (~4 characters)
A27: 1 million tokens | B27: roughly 750,000 words, about 10 novels or 1,500 pages
A28: 1 million tokens, in chat | B28: about 300 back-and-forth messages
A29: $1 (₹86) of AI spend | B29: covers roughly 2,000 chat messages

Sheet Running Costs
A1: RUNNING COSTS · everything it takes to keep Hatchin live
A2: The fixed monthly cost to keep the lights on, whether you have 1 user or 1,000. Payment fees and the AI cost of serving users are NOT here; those grow per user and live in Cost to Serve.
A4: What it is | B4: $/mo | C4: ₹/mo | D4: Note
A5: Database (Supabase Pro) | B5: =Assumptions!$B$87 -> 25 | C5: =B5*Assumptions!$B$69 -> 2150 | D5: auth, storage, Postgres
A6: Backend hosting (Fly.io) | B6: =Assumptions!$B$88 -> 15 | C6: =B6*Assumptions!$B$69 -> 1290 | D6: the Node server that runs the app
A7: Domain name | B7: 2 | C7: =B7*Assumptions!$B$69 -> 172 | D7: about $18 a year
A8: Transactional email (Resend) | B8: 8 | C8: =B8*Assumptions!$B$69 -> 688 | D8: signup, reset, notification emails
A9: Marketing email tool | B9: 30 | C9: =B9*Assumptions!$B$69 -> 2580 | D9: newsletters, onboarding sequences
A10: Error monitoring (Sentry) | B10: 26 | C10: =B10*Assumptions!$B$69 -> 2236 | D10: catches crashes before users complain
A11: Product analytics (PostHog) | B11: 0 | C11: =B11*Assumptions!$B$69 -> 0 | D11: free tier at this scale
A12: Uptime monitoring | B12: 7 | C12: =B12*Assumptions!$B$69 -> 602 | D12: alerts if the site goes down
A13: AI development and testing | B13: 30 | C13: =B13*Assumptions!$B$69 -> 2580 | D13: your own usage while building
A14: Backups and object storage | B14: 8 | C14: =B14*Assumptions!$B$69 -> 688 | D14: safety net for data
A15: Misc (SSL, CDN, small tools) | B15: 19 | C15: =B15*Assumptions!$B$69 -> 1634 | D15: Cloudflare free tier, certificates
A16: TOTAL to keep it live | B16: =SUM(B5:B15) -> 170 | C16: =B16*Assumptions!$B$69 -> 14620
A18: This total ($170) is the fixed burn used in Runway and Break-even. It barely grows until you hire; that is why margins are strong. Add a founder salary on the Assumptions tab to see real burn.

Sheet Usage Windows
A1: USAGE WINDOWS · the Claude-style cap that protects margin
A2: Autonomy (background AI work) draws from a budget that refills every 5 hours, plus a weekly ceiling. This bounds worst-case AI cost per user, which is what makes low prices and free trials financially safe.
A4: Tier | B4: Runs / 5h | C4: Weekly cap | D4: Max runs/mo | E4: Worst AI $ | F4: Worst AI ₹ | G4: Worst total $ | H4: Net rev $ | I4: Worst margin | J4: Typical margin
A5: Free (autonomy off) | B5: 0 | C5: 0 | D5: 0 | E5: 0 | F5: 0 | G5: ='Cost to Serve'!$B$13 -> 0.098 | H5: n/a | I5: n/a | J5: n/a
A6: Pro · US / UK ($19) | B6: 15 | C6: 200 | D6: =C6*52/12 -> 866.66667 | E6: =D6*Assumptions!$B$49 -> 7.8 | F6: =E6*Assumptions!$B$69 -> 670.8 | G6: =E6+('Cost to Serve'!$C$13-'Cost to Serve'!$C$6) -> 9.671 | H6: ='B2C Pricing'!$B$10 -> 19 | I6: =(H6-G6)/H6 -> 0.491 | J6: ='B2C Pricing'!$B$13 -> 0.83047368
A7: Pro · India (₹699) | B7: 10 | C7: 120 | D7: =C7*52/12 -> 520 | E7: =D7*Assumptions!$B$49 -> 4.68 | F7: =E7*Assumptions!$B$69 -> 402.48 | G7: =E7+('Cost to Serve'!$C$5+'B2C Pricing'!$D$9+Assumptions!$B$75+Assumptions!$B$78+Assumptions!$B$81) -> 5.8918186 | H7: ='B2C Pricing'!$D$10 -> 6.8880568 | I7: =(H7-G7)/H7 -> 0.14463269 | J7: ='B2C Pricing'!$D$13 -> 0.532379
A8: Studio ($39) | B8: 40 | C8: 600 | D8: =C8*52/12 -> 2600 | E8: =D8*Assumptions!$B$49 -> 23.4 | F8: =E8*Assumptions!$B$69 -> 2012.4 | G8: =E8+(2.2) -> 25.6 | H8: =39 -> 39 | I8: =(H8-G8)/H8 -> 0.34358974 | J8: =(H8-(2.2+300*Assumptions!$B$49))/H8 -> 0.87435897
A9: B2B seat ($29) | B9: 25 | C9: 350 | D9: =C9*52/12 -> 1516.6667 | E9: =D9*Assumptions!$B$49 -> 13.65 | F9: =E9*Assumptions!$B$69 -> 1173.9 | G9: =E9+('Cost to Serve'!$D$13-'Cost to Serve'!$D$6) -> 16.85 | H9: =29 -> 29 | I9: =(H9-G9)/H9 -> 0.41896552 | J9: =(H9-'Cost to Serve'!$D$13)/H9 -> 0.79655172
A11: WITHOUT a cap (why this matters)
A12: Scenario | B12: Runs/mo | E12: AI $ | F12: AI ₹ | G12: Total $ | H12: Net rev $ | I12: Margin
A13: Heavy India user, 50 runs/day, uncapped | B13: =50*30 -> 1500 | E13: =B13*Assumptions!$B$49 -> 13.5 | F13: =E13*Assumptions!$B$69 -> 1161 | G13: =E13+('Cost to Serve'!$C$5+'B2C Pricing'!$D$9+Assumptions!$B$75+Assumptions!$B$78+Assumptions!$B$81) -> 14.711819 | H13: ='B2C Pricing'!$D$10 -> 6.8880568 | I13: =(H13-G13)/H13 -> -1.1358446
A15: The cap turns a catastrophic loss into a safe, positive margin, at every price.
A16: Overage valve: a $5 (₹430) top-up buys +100 runs, or the cap prompts an upgrade. Extra revenue, never a surprise bill.
A18: IF A USER NEVER STOPS (maxes the cap every day and week) · the absolute ceiling
A19: Tier | B19: Runs/day | C19: $/day | D19: ₹/day | E19: Runs/week | F19: $/week | G19: ₹/week | H19: Runs/mo | I19: $/mo | J19: ₹/mo
A20: Pro · US / UK | B20: =C6/7 -> 28.571429 | C20: =B20*Assumptions!$B$49 -> 0.25714286 | D20: =C20*Assumptions!$B$69 -> 22.114286 | E20: =C6 -> 200 | F20: =E20*Assumptions!$B$49 -> 1.8 | G20: =F20*Assumptions!$B$69 -> 154.8 | H20: =C6*52/12 -> 866.66667 | I20: =H20*Assumptions!$B$49 -> 7.8 | J20: =I20*Assumptions!$B$69 -> 670.8
A21: Pro · India | B21: =C7/7 -> 17.142857 | C21: =B21*Assumptions!$B$49 -> 0.15428571 | D21: =C21*Assumptions!$B$69 -> 13.268571 | E21: =C7 -> 120 | F21: =E21*Assumptions!$B$49 -> 1.08 | G21: =F21*Assumptions!$B$69 -> 92.88 | H21: =C7*52/12 -> 520 | I21: =H21*Assumptions!$B$49 -> 4.68 | J21: =I21*Assumptions!$B$69 -> 402.48
A22: Studio | B22: =C8/7 -> 85.714286 | C22: =B22*Assumptions!$B$49 -> 0.77142857 | D22: =C22*Assumptions!$B$69 -> 66.342857 | E22: =C8 -> 600 | F22: =E22*Assumptions!$B$49 -> 5.4 | G22: =F22*Assumptions!$B$69 -> 464.4 | H22: =C8*52/12 -> 2600 | I22: =H22*Assumptions!$B$49 -> 23.4 | J22: =I22*Assumptions!$B$69 -> 2012.4
A23: B2B seat | B23: =C9/7 -> 50 | C23: =B23*Assumptions!$B$49 -> 0.45 | D23: =C23*Assumptions!$B$69 -> 38.7 | E23: =C9 -> 350 | F23: =E23*Assumptions!$B$49 -> 3.15 | G23: =F23*Assumptions!$B$69 -> 270.9 | H23: =C9*52/12 -> 1516.6667 | I23: =H23*Assumptions!$B$49 -> 13.65 | J23: =I23*Assumptions!$B$69 -> 1173.9
A25: This is the MOST a user can ever cost us in AI. When the allowance finishes, background work pauses until it resets (5 hours, or the week); we run nothing in the meantime, so there is no runaway cost and the reset itself costs nothing. Even a user who never sleeps cannot pass the weekly ceiling. The $/mo column here is the same 'worst case' cost as the table above.

Sheet B2C Pricing
A1: B2C PRICING BY REGION
A2: Headline prices (row 5) are your levers. India price is tax-inclusive; UK is VAT-inclusive.
A4: Metric | B4: US | C4: UK | D4: India
A5: Headline price (local) | B5: 19 | C5: 15 | D5: 699
A6: Currency | B6: USD | C6: GBP | D6: INR
A7: Headline price (USD) | B7: =B5 -> 19 | C7: =C5*Assumptions!$B$70 -> 19.05 | D7: =D5/Assumptions!$B$69 -> 8.127907
A8: Net of tax (USD) | B8: =B7 -> 19 | C8: =C7/(1+Assumptions!$B$68) -> 15.875 | D8: =D7/(1+Assumptions!$B$67) -> 6.8880568
A9: Payment fee (memo · already inside cost) | B9: =B7*Assumptions!$B$62+Assumptions!$B$63 -> 0.851 | C9: =C7*Assumptions!$B$64+Assumptions!$B$65*Assumptions!$B$70 -> 0.53975 | D9: =D7*Assumptions!$B$66 -> 0.1918186
A10: REVENUE after tax (USD) | B10: =B8 -> 19 | C10: =C8 -> 15.875 | D10: =D8 -> 6.8880568
A11: Cost to serve (incl payment fee) | B11: ='Cost to Serve'!$C$13 -> 3.221 | C11: ='Cost to Serve'!$C$13 -> 3.221 | D11: ='Cost to Serve'!$C$13 -> 3.221
A12: CONTRIBUTION MARGIN ($) | B12: =B10-B11 -> 15.779 | C12: =C10-C11 -> 12.654 | D12: =D10-D11 -> 3.6670568
A13: GROSS MARGIN % | B13: =B12/B10 -> 0.83047368 | C13: =C12/C10 -> 0.79710236 | D13: =D12/D10 -> 0.532379
A16: INDIA MARGIN-COMPRESSION CURVE
A17: Price is global (USD LLM cost is fixed). Watch where the line crosses zero.
A18: India price (₹) | B18: Net rev (USD) | C18: − loaded cost | D18: Margin %
A19: 899 | B19: =(A19/Assumptions!$B$69)/(1+Assumptions!$B$67) -> 8.8588885 | C19: =B19-'Cost to Serve'!$C$13 -> 5.6378885 | D19: =C19/B19 -> 0.63641037
A20: 699 | B20: =(A20/Assumptions!$B$69)/(1+Assumptions!$B$67) -> 6.8880568 | C20: =B20-'Cost to Serve'!$C$13 -> 3.6670568 | D20: =C20/B20 -> 0.532379
A21: 499 | B21: =(A21/Assumptions!$B$69)/(1+Assumptions!$B$67) -> 4.9172251 | C21: =B21-'Cost to Serve'!$C$13 -> 1.6962251 | D21: =C21/B21 -> 0.34495575
A22: 399 | B22: =(A22/Assumptions!$B$69)/(1+Assumptions!$B$67) -> 3.9318092 | C22: =B22-'Cost to Serve'!$C$13 -> 0.71080922 | D22: =C22/B22 -> 0.18078426
A23: 350 | B23: =(A23/Assumptions!$B$69)/(1+Assumptions!$B$67) -> 3.4489555 | C23: =B23-'Cost to Serve'!$C$13 -> 0.22795546 | D23: =C23/B23 -> 0.066094057
A24: 299 | B24: =(A24/Assumptions!$B$69)/(1+Assumptions!$B$67) -> 2.9463934 | C24: =B24-'Cost to Serve'!$C$13 -> -0.27460662 | D24: =C24/B24 -> -0.093200936
A25: ← break-even ≈ ₹350/mo (fully-loaded)

Sheet B2C Personas
A1: B2C PERSONAS · five real people, each run through the cap
A2: The headline margins use 'Daily Builder Devi' (the average). Here is the full spread. 'Runs billed' = the smaller of what they want and the cap, which is how the cap protects you. All money in $ and ₹.
A4: Persona | B4: Tier | C4: Chat/mo | D4: Runs wanted | E4: Cap/mo | F4: Runs billed | G4: AI cost $ | H4: Non-AI $ | I4: Total cost $ | J4: You keep $ | K4: Profit $ | L4: Margin | M4: Profit ₹
A5: Curious Lurker | B5: Free | C5: 150 | D5: 0 | E5: 0 | F5: =MIN(D5,E5) -> 0 | G5: =C5*Assumptions!$B$47+F5*Assumptions!$B$49 -> 0.03 | H5: 0.07 | I5: =G5+H5 -> 0.1 | J5: =0 -> 0 | K5: =J5-I5 -> -0.1 | L5: =IF(J5=0,"n/a",K5/J5) -> n/a | M5: =K5*Assumptions!$B$69 -> -8.6
A6: Side-Project Sam | B6: Pro · US | C6: 450 | D6: 60 | E6: 867 | F6: =MIN(D6,E6) -> 60 | G6: =C6*Assumptions!$B$48+F6*Assumptions!$B$49 -> 0.675 | H6: 1.6 | I6: =G6+H6 -> 2.275 | J6: ='B2C Pricing'!$B$10 -> 19 | K6: =J6-I6 -> 16.725 | L6: =IF(J6=0,"n/a",K6/J6) -> 0.88026316 | M6: =K6*Assumptions!$B$69 -> 1438.35
A7: Daily Builder Devi | B7: Pro · US | C7: 900 | D7: 150 | E7: 867 | F7: =MIN(D7,E7) -> 150 | G7: =C7*Assumptions!$B$48+F7*Assumptions!$B$49 -> 1.62 | H7: 1.6 | I7: =G7+H7 -> 3.22 | J7: ='B2C Pricing'!$B$10 -> 19 | K7: =J7-I7 -> 15.78 | L7: =IF(J7=0,"n/a",K7/J7) -> 0.83052632 | M7: =K7*Assumptions!$B$69 -> 1357.08
A8: Devi, in India | B8: Pro · India | C8: 900 | D8: 150 | E8: 520 | F8: =MIN(D8,E8) -> 150 | G8: =C8*Assumptions!$B$48+F8*Assumptions!$B$49 -> 1.62 | H8: 1.6 | I8: =G8+H8 -> 3.22 | J8: ='B2C Pricing'!$D$10 -> 6.8880568 | K8: =J8-I8 -> 3.6680568 | L8: =IF(J8=0,"n/a",K8/J8) -> 0.53252418 | M8: =K8*Assumptions!$B$69 -> 315.45288
A9: Power User Priya | B9: Pro · US | C9: 1800 | D9: 1200 | E9: 867 | F9: =MIN(D9,E9) -> 867 | G9: =C9*Assumptions!$B$48+F9*Assumptions!$B$49 -> 8.343 | H9: 1.6 | I9: =G9+H9 -> 9.943 | J9: ='B2C Pricing'!$B$10 -> 19 | K9: =J9-I9 -> 9.057 | L9: =IF(J9=0,"n/a",K9/J9) -> 0.47668421 | M9: =K9*Assumptions!$B$69 -> 778.902
A10: Agency Ace | B10: Studio | C10: 2400 | D10: 900 | E10: 2600 | F10: =MIN(D10,E10) -> 900 | G10: =C10*Assumptions!$B$48+F10*Assumptions!$B$49 -> 8.82 | H10: 2.2 | I10: =G10+H10 -> 11.02 | J10: =39 -> 39 | K10: =J10-I10 -> 27.98 | L10: =IF(J10=0,"n/a",K10/J10) -> 0.7174359 | M10: =K10*Assumptions!$B$69 -> 2406.28
A12: Same Priya, if there were NO cap
A13: Power User Priya (uncapped) | B13: Pro · US | C13: 1800 | D13: 1200 | E13: 1200 | F13: =MIN(D13,E13) -> 1200 | G13: =C13*Assumptions!$B$48+F13*Assumptions!$B$49 -> 11.34 | H13: 1.6 | I13: =G13+H13 -> 12.94 | J13: ='B2C Pricing'!$B$10 -> 19 | K13: =J13-I13 -> 6.06 | L13: =K13/J13 -> 0.31894737 | M13: =K13*Assumptions!$B$69 -> 521.16
A15: Read Priya's two rows together: the cap lifts her margin from ~27% to ~43% and nudges her to upgrade to Studio.

Sheet B2B Model
A1: B2B MODEL · per-seat, sell to the whole team
A2: The profit engine: one account is worth ~23× a single B2C Pro. Blue = inputs.
A4: Metric | B4: 10-seat co. | C4: 50-seat co.
A5: Seat price (volume tier) | B5: 29 | C5: 27
A6: Seats | B6: 10 | C6: 50
A7: Active seats (70%) | B7: =B6*0.7 -> 7 | C7: =C6*0.7 -> 35
A8: Monthly account revenue (MRR) | B8: =B5*B6 -> 290 | C8: =C5*C6 -> 1350
A9: ARR | B9: =B8*12 -> 3480 | C9: =C8*12 -> 16200
A10: LLM cost (active seats) | B10: =B7*'Cost to Serve'!$D$7 -> 22.05 | C10: =C7*'Cost to Serve'!$D$7 -> 110.25
A11: Payment fee | B11: =B8*Assumptions!$B$62+Assumptions!$B$63 -> 8.71 | C11: =C8*Assumptions!$B$62+Assumptions!$B$63 -> 39.45
A12: Variable infra | B12: 1.5 | C12: 5
A13: Admin / SSO / support / CSM | B13: 15 | C13: 50
A14: COGS | B14: =B10+B11+B12+B13 -> 47.26 | C14: =C10+C11+C12+C13 -> 204.7
A15: Gross profit | B15: =B8-B14 -> 242.74 | C15: =C8-C14 -> 1145.3
A16: Gross margin % | B16: =B15/B8 -> 0.83703448 | C16: =C15/C8 -> 0.84837037
A17: Company monthly churn | B17: =Assumptions!$B$98 -> 0.025 | C17: =Assumptions!$B$98 -> 0.025
A18: ACCOUNT LTV | B18: =B15/B17 -> 9709.6 | C18: =C15/C17 -> 45812
A19: LTV per seat | B19: =(B15/B6)/B17 -> 970.96 | C19: =(C15/C6)/C17 -> 916.24

Sheet Company Sizes
A1: COMPANY SIZES · five B2B accounts, small to large
A2: Margin holds around 83% at every size, and lifetime value grows fast. Autonomy is a shared pool that scales with seats, so bigger teams simply get a bigger budget. All money in $ and ₹.
A4: Company | B4: Seats | C4: Seat $ | D4: They pay/mo $ | E4: They pay/mo ₹ | F4: Active seats | G4: AI $ | H4: Payment $ | I4: Infra $ | J4: Admin $ | K4: Your cost $ | L4: You profit $ | M4: Margin | N4: Worth (LTV) $ | O4: Worth (LTV) ₹
A5: Freelance duo | B5: 3 | C5: 34 | D5: =B5*C5 -> 102 | E5: =D5*Assumptions!$B$69 -> 8772 | F5: =B5*0.7 -> 2.1 | G5: =F5*'Cost to Serve'!$D$7 -> 6.615 | H5: =D5*Assumptions!$B$62+Assumptions!$B$63 -> 3.258 | I5: =B5*Assumptions!$B$76 -> 0.45 | J5: 8 | K5: =G5+H5+I5+J5 -> 18.323 | L5: =D5-K5 -> 83.677 | M5: =L5/D5 -> 0.82036275 | N5: =L5/Assumptions!$B$98 -> 3347.08 | O5: =N5*Assumptions!$B$69 -> 287848.88
A6: Small startup | B6: 5 | C6: 32 | D6: =B6*C6 -> 160 | E6: =D6*Assumptions!$B$69 -> 13760 | F6: =B6*0.7 -> 3.5 | G6: =F6*'Cost to Serve'!$D$7 -> 11.025 | H6: =D6*Assumptions!$B$62+Assumptions!$B$63 -> 4.94 | I6: =B6*Assumptions!$B$76 -> 0.75 | J6: 10 | K6: =G6+H6+I6+J6 -> 26.715 | L6: =D6-K6 -> 133.285 | M6: =L6/D6 -> 0.83303125 | N6: =L6/Assumptions!$B$98 -> 5331.4 | O6: =N6*Assumptions!$B$69 -> 458500.4
A7: Growing team | B7: 10 | C7: 29 | D7: =B7*C7 -> 290 | E7: =D7*Assumptions!$B$69 -> 24940 | F7: =B7*0.7 -> 7 | G7: =F7*'Cost to Serve'!$D$7 -> 22.05 | H7: =D7*Assumptions!$B$62+Assumptions!$B$63 -> 8.71 | I7: =B7*Assumptions!$B$76 -> 1.5 | J7: 15 | K7: =G7+H7+I7+J7 -> 47.26 | L7: =D7-K7 -> 242.74 | M7: =L7/D7 -> 0.83703448 | N7: =L7/Assumptions!$B$98 -> 9709.6 | O7: =N7*Assumptions!$B$69 -> 835025.6
A8: Scaling SMB | B8: 25 | C8: 28 | D8: =B8*C8 -> 700 | E8: =D8*Assumptions!$B$69 -> 60200 | F8: =B8*0.7 -> 17.5 | G8: =F8*'Cost to Serve'!$D$7 -> 55.125 | H8: =D8*Assumptions!$B$62+Assumptions!$B$63 -> 20.6 | I8: =B8*Assumptions!$B$76 -> 3.75 | J8: 30 | K8: =G8+H8+I8+J8 -> 109.475 | L8: =D8-K8 -> 590.525 | M8: =L8/D8 -> 0.84360714 | N8: =L8/Assumptions!$B$98 -> 23621 | O8: =N8*Assumptions!$B$69 -> 2031406
A9: Larger SMB | B9: 50 | C9: 27 | D9: =B9*C9 -> 1350 | E9: =D9*Assumptions!$B$69 -> 116100 | F9: =B9*0.7 -> 35 | G9: =F9*'Cost to Serve'!$D$7 -> 110.25 | H9: =D9*Assumptions!$B$62+Assumptions!$B$63 -> 39.45 | I9: =B9*Assumptions!$B$76 -> 7.5 | J9: 50 | K9: =G9+H9+I9+J9 -> 207.2 | L9: =D9-K9 -> 1142.8 | M9: =L9/D9 -> 0.84651852 | N9: =L9/Assumptions!$B$98 -> 45712 | O9: =N9*Assumptions!$B$69 -> 3931232

Sheet P&L Scenarios
A1: BLENDED P&L · three scales
A2: B2C from signups×conversion. B2B is an overlay (separate motion) · blue cells per scenario.
A4: Line | B4: 100 signups | C4: 1,000 signups | D4: 10,000 signups
A5: Signups | B5: 100 | C5: 1000 | D5: 10000
A6: Conversion % | B6: =Assumptions!$B$95 -> 0.03 | C6: =Assumptions!$B$95 -> 0.03 | D6: =Assumptions!$B$95 -> 0.03
A7: Free users | B7: =B5*(1-B6) -> 97 | C7: =C5*(1-C6) -> 970 | D7: =D5*(1-D6) -> 9700
A8: B2C Pro customers | B8: =B5*B6 -> 3 | C8: =C5*C6 -> 30 | D8: =D5*D6 -> 300
A9: Blended B2C ARPU (USD) | B9: 16.5 | C9: 16.5 | D9: 16.5
A10: B2B seats (accounts) | B10: 0 (0) | C10: 30 (2) | D10: 400 (20)
A11: B2C MRR | B11: =B8*B9 -> 49.5 | C11: =C8*C9 -> 495 | D11: =D8*D9 -> 4950
A12: B2B MRR | B12: 0 | C12: 840 | D12: 10800
A13: TOTAL MRR | B13: =B11+B12 -> 49.5 | C13: =C11+C12 -> 1335 | D13: =D11+D12 -> 15750
A14: ARR | B14: =B13*12 -> 594 | C14: =C13*12 -> 16020 | D14: =D13*12 -> 189000
A15: COGS · B2C paid | B15: =B8*'Cost to Serve'!$C$13 -> 9.663 | C15: =C8*'Cost to Serve'!$C$13 -> 96.63 | D15: =D8*'Cost to Serve'!$C$13 -> 966.3
A16: COGS · B2B | B16: 0 | C16: 180 | D16: 1820
A17: COGS · free-tier drag | B17: =B7*'Cost to Serve'!$B$13 -> 9.506 | C17: =C7*'Cost to Serve'!$B$13 -> 95.06 | D17: =D7*'Cost to Serve'!$B$13 -> 950.6
A18: GROSS PROFIT | B18: =B13-B15-B16-B17 -> 30.331 | C18: =C13-C15-C16-C17 -> 963.31 | D18: =D13-D15-D16-D17 -> 12013.1
A19: Gross margin % | B19: =B18/B13 -> 0.61274747 | C19: =C18/C13 -> 0.72158052 | D19: =D18/D13 -> 0.76273651
A20: Support (VA step cost) | B20: 0 | C20: 0 | D20: 1500
A21: Fixed infra + tools | B21: 110 | C21: 140 | D21: 550
A22: OPERATING PROFIT / (LOSS) | B22: =B18-B20-B21 -> -79.669 | C22: =C18-C20-C21 -> 823.31 | D22: =D18-D20-D21 -> 9963.1

Sheet Growth Forecast
A1: GROWTH FORECAST · an illustrative 18-month path (a plan, not a promise)
A2: Pre-revenue. This is one reasonable way growth could go if the plan works. Signups and company count are the inputs (blue); the rest follows from the model. Default-alive (~$227 MRR) is crossed almost at once.
A4: Quarter | B4: Signups | C4: Paying | D4: Companies | E4: Solo MRR $ | F4: Company MRR $ | G4: Total MRR $ | H4: Run-rate ARR $ | I4: Total MRR ₹
A5: Q1 | B5: 200 | C5: =B5*Assumptions!$B$95 -> 6 | D5: 0 | E5: =C5*'P&L Scenarios'!$B$9 -> 99 | F5: =D5*'B2B Model'!$B$8 -> 0 | G5: =E5+F5 -> 99 | H5: =G5*12 -> 1188 | I5: =G5*Assumptions!$B$69 -> 8514
A6: Q2 | B6: 600 | C6: =B6*Assumptions!$B$95 -> 18 | D6: 1 | E6: =C6*'P&L Scenarios'!$B$9 -> 297 | F6: =D6*'B2B Model'!$B$8 -> 290 | G6: =E6+F6 -> 587 | H6: =G6*12 -> 7044 | I6: =G6*Assumptions!$B$69 -> 50482
A7: Q3 | B7: 1500 | C7: =B7*Assumptions!$B$95 -> 45 | D7: 3 | E7: =C7*'P&L Scenarios'!$B$9 -> 742.5 | F7: =D7*'B2B Model'!$B$8 -> 870 | G7: =E7+F7 -> 1612.5 | H7: =G7*12 -> 19350 | I7: =G7*Assumptions!$B$69 -> 138675
A8: Q4 | B8: 3000 | C8: =B8*Assumptions!$B$95 -> 90 | D8: 6 | E8: =C8*'P&L Scenarios'!$B$9 -> 1485 | F8: =D8*'B2B Model'!$B$8 -> 1740 | G8: =E8+F8 -> 3225 | H8: =G8*12 -> 38700 | I8: =G8*Assumptions!$B$69 -> 277350
A9: Q5 | B9: 6000 | C9: =B9*Assumptions!$B$95 -> 180 | D9: 12 | E9: =C9*'P&L Scenarios'!$B$9 -> 2970 | F9: =D9*'B2B Model'!$B$8 -> 3480 | G9: =E9+F9 -> 6450 | H9: =G9*12 -> 77400 | I9: =G9*Assumptions!$B$69 -> 554700
A10: Q6 | B10: 10000 | C10: =B10*Assumptions!$B$95 -> 300 | D10: 20 | E10: =C10*'P&L Scenarios'!$B$9 -> 4950 | F10: =D10*'B2B Model'!$B$8 -> 5800 | G10: =E10+F10 -> 10750 | H10: =G10*12 -> 129000 | I10: =G10*Assumptions!$B$69 -> 924500
A12: Why this is reachable: ~550 signups/month on average (launch burst first, then referrals + affiliates + tool partnerships; no paid ads), 3 in 100 pay, and ~1 company signs per month. Those three inputs are the plan's real assumptions; the money then follows by arithmetic. Uses conservative small (10-seat) companies, so larger accounts lift this further.

Sheet Sensitivity
A1: SENSITIVITY · what if things go worse or better
A2: Same scale (10,000 signups). Change the three big unknowns and see the monthly gross profit. The headline: even the downside case makes money.
A4: Driver | B4: Downside | C4: Base case | D4: Upside
A5: Free to paid conversion | B5: 0.02 | C5: 0.03 | D5: 0.05
A6: AI price vs today | B6: 2 | C6: 1 | D6: 0.7
A7: Companies (accounts) | B7: 12 | C7: 20 | D7: 30
A8: Signups (fixed) | B8: 10000 | C8: 10000 | D8: 10000
A10: Paying solos | B10: =B8*B5 -> 200 | C10: =C8*C5 -> 300 | D10: =D8*D5 -> 500
A11: Solo MRR $ | B11: =B10*'P&L Scenarios'!$B$9 -> 3300 | C11: =C10*'P&L Scenarios'!$B$9 -> 4950 | D11: =D10*'P&L Scenarios'!$B$9 -> 8250
A12: Company MRR $ | B12: =B7*'B2B Model'!$B$8 -> 3480 | C12: =C7*'B2B Model'!$B$8 -> 5800 | D12: =D7*'B2B Model'!$B$8 -> 8700
A13: Total MRR $ | B13: =B11+B12 -> 6780 | C13: =C11+C12 -> 10750 | D13: =D11+D12 -> 16950
A14: Cost to serve (with AI multiplier) $ | B14: =B10*(1.6+1.8*B6)+B7*(25+24*B6)+(B8-B10)*(0.07+0.05*B6) -> 3582 | C14: =C10*(1.6+1.8*C6)+C7*(25+24*C6)+(C8-C10)*(0.07+0.05*C6) -> 3164 | D14: =D10*(1.6+1.8*D6)+D7*(25+24*D6)+(D8-D10)*(0.07+0.05*D6) -> 3681.5
A15: Monthly gross profit $ | B15: =B13-B14 -> 3198 | C15: =C13-C14 -> 7586 | D15: =D13-D14 -> 13268.5
A16: Monthly gross profit ₹ | B16: =B15*Assumptions!$B$69 -> 275028 | C16: =C15*Assumptions!$B$69 -> 652396 | D16: =D15*Assumptions!$B$69 -> 1141091
A18: Even the downside stays profitable. Conversion and AI price move the result most, so watch those two.

Sheet Market Size
A1: MARKET SIZE · how big is this (rough, top-down)
A2: Illustrative sizing to show the ceiling is high, not a promise. All inputs are estimates you can refine. The point: you need only a tiny share to build a real business.
A4: Item | B4: Value | C4: As money | D4: Note
A5: Reachable customers (US/UK/India + similar) | B5: 10000000 | D5: EST · solopreneurs, freelancers, small teams who pay for tools
A6: Blended price per customer / year | B6: 200 | D6: EST · mix of solo and company plans
A7: Reachable market / year | C7: =B5*B6 -> 2000000000
A9: If you capture 0.5% (50,000 customers) | C9: =B5*0.005*B6 -> 10000000 | D9: a real, venture-scale business
A10: If you capture 1% (100,000 customers) | C10: =B5*0.01*B6 -> 20000000
A12: Wider market, long term (all small biz + knowledge freelancers globally): 100M+ people, a $10B+ per year market. Directional only.
A13: The takeaway: capturing well under 1% of the reachable market is a strong outcome. Size is not the constraint; execution is.

Sheet Key Metrics
A1: KEY METRICS · the numbers investors screen on
A2: The good and the honest bad. The headline weakness: individual customers churn fast, so the durable revenue is companies. Retention math is (1 minus monthly churn) to the power 12.
A4: Metric | B4: Value | C4: What it means
A5: Blended gross margin | B5: ='P&L Scenarios'!$D$19 -> 0.76273651 | C5: Kept from each sale after costs. Very healthy for software.
A6: B2C monthly churn | B6: =Assumptions!$B$96 -> 0.06 | C6: Individuals who cancel each month.
A7: B2C yearly retention | B7: =POWER(1-Assumptions!$B$96,12) -> 0.47592031 | C7: Only about half of individuals stay a year. This is the weak spot.
A8: India B2C yearly retention | B8: =POWER(1-Assumptions!$B$97,12) -> 0.36766639 | C8: Lower again, due to card renewal failures. Push annual plans.
A9: Company monthly churn | B9: =Assumptions!$B$98 -> 0.025 | C9: Companies are far stickier.
A10: Company yearly retention | B10: =POWER(1-Assumptions!$B$98,12) -> 0.73799835 | C10: About three quarters of companies stay a year.
A11: Company seat expansion / year | B11: 0.25 | C11: EST · surviving teams add seats over time.
A12: Company net revenue retention | B12: =POWER(1-Assumptions!$B$98,12)*(1+B11) -> 0.92249793 | C12: Retention plus seat growth. Aim to push this above 100%.
A13: B2C net revenue retention | B13: =POWER(1-Assumptions!$B$96,12) -> 0.47592031 | C13: Little expansion, so about equal to retention. Leaky.
A14: LTV to CAC · best (company) | B14: ='CAC & LTV'!$G$5 -> 4.185 | C14: Every $1 to win a company returns ~$11. Excellent (target is 3x+).
A15: LTV to CAC · individual (organic) | B15: ='CAC & LTV'!$G$7 -> 3.978 | C15: Healthy, as long as you avoid paid ads.
A16: CAC payback · individual | B16: ='CAC & LTV'!$H$7 -> 4.1897101 | C16: Months to earn back the cost of winning a customer.
A17: Rule of 40 (growth% + margin%) | B17: well above 40 | C17: In the growth phase, growth alone clears it. A strong sign.
A18: Burn multiple (lean, $0 salary) | B18: near 0 | C18: Dollars burned per dollar of new revenue. Near 0 is very capital efficient.
A21: The story: individuals are a leaky bucket (about half leave in a year), companies are durable and grow. So the plan leans on companies for lasting revenue, and on annual plans plus better onboarding to fix the B2C leak. That is the single most important thing to improve.

Sheet OpEx & Taxes
A1: OPEX & TAXES · the real cost of a team, and tax on profit
A2: Being straight: today's $170 burn is a solo founder. A funded company has salaries, and a profitable one pays tax. Here is the honest picture at 10,000 signups under three team sizes.
A4: HIRING PLAN (illustrative)
A5: Phase | B5: People cost/mo $ | C5: Infra+tools/mo $ | D5: Total OpEx/mo $ | E5: Total OpEx/mo ₹
A6: Now (solo, pre-revenue) | B6: 0 | C6: 170 | D6: =B6+C6 -> 170 | E6: =D6*Assumptions!$B$69 -> 14620
A7: Small team (founder + 2) | B7: 6000 | C7: 500 | D7: =B7+C7 -> 6500 | E7: =D7*Assumptions!$B$69 -> 559000
A8: Growth team (5 people) | B8: 22000 | C8: 1200 | D8: =B8+C8 -> 23200 | E8: =D8*Assumptions!$B$69 -> 1995200
A10: PROFIT AT 10,000 SIGNUPS, THREE TEAM SIZES
A11: Corporate tax rate | B11: 0.25 | C11: EST · ~25% India / 21% US on profit
A12: Line | B12: Lean (solo) | C12: Small team | D12: Growth team
A13: Revenue / mo | B13: ='P&L Scenarios'!$D$13 -> 15750 | C13: ='P&L Scenarios'!$D$13 -> 15750 | D13: ='P&L Scenarios'!$D$13 -> 15750
A14: Gross profit / mo | B14: ='P&L Scenarios'!$D$18 -> 12013.1 | C14: ='P&L Scenarios'!$D$18 -> 12013.1 | D14: ='P&L Scenarios'!$D$18 -> 12013.1
A15: Team + fixed OpEx / mo | B15: =D6 -> 170 | C15: =D7 -> 6500 | D15: =D8 -> 23200
A16: Operating profit / mo | B16: =B14-B15 -> 11843.1 | C16: =C14-C15 -> 5513.1 | D16: =D14-D15 -> -11186.9
A17: Corporate tax | B17: =IF(B16>0,B16*$B$11,0) -> 2960.775 | C17: =IF(C16>0,C16*$B$11,0) -> 1378.275 | D17: =IF(D16>0,D16*$B$11,0) -> 0
A18: NET PROFIT / mo | B18: =B16-B17 -> 8882.325 | C18: =C16-C17 -> 4134.825 | D18: =D16-D17 -> -11186.9
A19: NET PROFIT / mo ₹ | B19: =B18*Assumptions!$B$69 -> 763879.95 | C19: =C18*Assumptions!$B$69 -> 355594.95 | D19: =D18*Assumptions!$B$69 -> -962073.4
A21: The honest read: run lean and it is very profitable and pays tax. Hire a full team to grow faster and you run a planned loss (investing in growth), which is a choice, not a failure. Both are normal. The '$9,692 profit' shown elsewhere is the lean case.

Sheet Runway
A1: RUNWAY & BURN
A2: At $0 founder draw the burn is tiny · this is a 'land B2B accounts' problem, not a cash-cliff problem.
A4: MONTHLY BURN COMPONENTS
A5: Component | B5: $/mo
A6: Infra (Supabase+Fly+domain) | B6: =Assumptions!$B$87+Assumptions!$B$88+Assumptions!$B$89 -> 50
A7: Tools / monitoring / analytics | B7: =Assumptions!$B$90 -> 120
A8: Founder draw | B8: =Assumptions!$B$91 -> 0
A9: TOTAL MONTHLY BURN | B9: =SUM(B6:B8) -> 170
A10: Current MRR | B10: 0
A12: RUNWAY (months) = cash ÷ (burn − MRR)
A13: Founder draw | B13: Burn/mo | C13: $10k cash | D13: $25k cash | E13: $50k cash
A14: 0 | B14: =Assumptions!$B$87+Assumptions!$B$88+Assumptions!$B$89+Assumptions!$B$90+A14 -> 170 | C14: =IF((B14-$B$10)<=0,"∞",10000/(B14-$B$10)) -> 58.823529 | D14: =IF((B14-$B$10)<=0,"∞",25000/(B14-$B$10)) -> 147.05882 | E14: =IF((B14-$B$10)<=0,"∞",50000/(B14-$B$10)) -> 294.11765
A15: 2000 | B15: =Assumptions!$B$87+Assumptions!$B$88+Assumptions!$B$89+Assumptions!$B$90+A15 -> 2170 | C15: =IF((B15-$B$10)<=0,"∞",10000/(B15-$B$10)) -> 4.6082949 | D15: =IF((B15-$B$10)<=0,"∞",25000/(B15-$B$10)) -> 11.520737 | E15: =IF((B15-$B$10)<=0,"∞",50000/(B15-$B$10)) -> 23.041475
A16: 3000 | B16: =Assumptions!$B$87+Assumptions!$B$88+Assumptions!$B$89+Assumptions!$B$90+A16 -> 3170 | C16: =IF((B16-$B$10)<=0,"∞",10000/(B16-$B$10)) -> 3.1545741 | D16: =IF((B16-$B$10)<=0,"∞",25000/(B16-$B$10)) -> 7.8864353 | E16: =IF((B16-$B$10)<=0,"∞",50000/(B16-$B$10)) -> 15.772871
A17: 5000 | B17: =Assumptions!$B$87+Assumptions!$B$88+Assumptions!$B$89+Assumptions!$B$90+A17 -> 5170 | C17: =IF((B17-$B$10)<=0,"∞",10000/(B17-$B$10)) -> 1.934236 | D17: =IF((B17-$B$10)<=0,"∞",25000/(B17-$B$10)) -> 4.8355899 | E17: =IF((B17-$B$10)<=0,"∞",50000/(B17-$B$10)) -> 9.6711799
A20: DEFAULT-ALIVE · MRR needed to break even
A21: Founder draw | B21: Break-even MRR | C21: ≈ US Pro subs | D21: ≈ B2B 10-seat accts
A22: 0 | B22: =(Assumptions!$B$87+Assumptions!$B$88+Assumptions!$B$89+Assumptions!$B$90+A22)/0.75 -> 226.66667 | C22: =B22/'B2C Pricing'!$B$10 -> 11.929825 | D22: =B22/'B2B Model'!$B$8 -> 0.7816092
A23: 2000 | B23: =(Assumptions!$B$87+Assumptions!$B$88+Assumptions!$B$89+Assumptions!$B$90+A23)/0.75 -> 2893.3333 | C23: =B23/'B2C Pricing'!$B$10 -> 152.2807 | D23: =B23/'B2B Model'!$B$8 -> 9.9770115
A24: 3000 | B24: =(Assumptions!$B$87+Assumptions!$B$88+Assumptions!$B$89+Assumptions!$B$90+A24)/0.75 -> 4226.6667 | C24: =B24/'B2C Pricing'!$B$10 -> 222.45614 | D24: =B24/'B2B Model'!$B$8 -> 14.574713
A25: 5000 | B25: =(Assumptions!$B$87+Assumptions!$B$88+Assumptions!$B$89+Assumptions!$B$90+A25)/0.75 -> 6893.3333 | C25: =B25/'B2C Pricing'!$B$10 -> 362.80702 | D25: =B25/'B2B Model'!$B$8 -> 23.770115

Sheet CAC & LTV
A1: CAC / LTV by region & motion
A2: LTV = ARPU × margin ÷ churn. Green rows are healthy (≥3:1); red are underwater.
A4: Segment / motion | B4: ARPU/mo | C4: GM % | D4: Churn/mo | E4: LTV | F4: CAC | G4: LTV:CAC | H4: Payback (mo)
A5: B2C US · organic | B5: 15.5 | C5: 0.81 | D5: 0.06 | E5: =B5*C5/D5 -> 209.25 | F5: 50 | G5: =E5/F5 -> 4.185 | H5: =F5/(B5*C5) -> 3.9824771
A6: B2C US · paid | B6: 15.5 | C6: 0.81 | D6: 0.06 | E6: =B6*C6/D6 -> 209.25 | F6: 200 | G6: =E6/F6 -> 1.04625 | H6: =F6/(B6*C6) -> 15.929908
A7: B2C UK · organic | B7: 15.3 | C7: 0.78 | D7: 0.06 | E7: =B7*C7/D7 -> 198.9 | F7: 50 | G7: =E7/F7 -> 3.978 | H7: =F7/(B7*C7) -> 4.1897101
A8: B2C India · organic | B8: 6.7 | C8: 0.49 | D8: 0.08 | E8: =B8*C8/D8 -> 41.0375 | F8: 25 | G8: =E8/F8 -> 1.6415 | H8: =F8/(B8*C8) -> 7.6149863
A9: B2C India · paid | B9: 6.7 | C9: 0.49 | D9: 0.08 | E9: =B9*C9/D9 -> 41.0375 | F9: 150 | G9: =E9/F9 -> 0.27358333 | H9: =F9/(B9*C9) -> 45.689918
A10: B2B account · self-serve | B10: 290 | C10: 0.83 | D10: 0.025 | E10: =B10*C10/D10 -> 9628 | F10: 600 | G10: =E10/F10 -> 16.046667 | H10: =F10/(B10*C10) -> 2.4927295
A11: B2B account · SMB sales (15-seat) | B11: 405 | C11: 0.83 | D11: 0.025 | E11: =B11*C11/D11 -> 13446 | F11: 1200 | G11: =E11/F11 -> 11.205 | H11: =F11/(B11*C11) -> 3.5698349
A13: Partnership-led CAC (from co-marketing analysis)
A14: B2C paying via partnerships | B14: ~$40
A15: B2B account via partnerships | B15: ~$80
A16: vs paid ads (B2C / B2B) | B16: $150-400 / $300-800

Sheet Break-even
A1: BREAK-EVEN · units to cover fixed costs
A2: One healthy B2B account covers the whole base burn. That is the punchline.
A4: Fixed-cost target | B4: US B2C Pro users | C4: OR B2B 10-seat accounts
A5: Base fixed ($170/mo, draw $0) | B5: =(Assumptions!$B$87+Assumptions!$B$88+Assumptions!$B$89+Assumptions!$B$90)/'B2C Pricing'!$B$12 -> 10.773813 | C5: =(Assumptions!$B$87+Assumptions!$B$88+Assumptions!$B$89+Assumptions!$B$90)/'B2B Model'!$B$15 -> 0.70033781
A6: + $3,000 founder draw | B6: =(Assumptions!$B$87+Assumptions!$B$88+Assumptions!$B$89+Assumptions!$B$90+3000)/'B2C Pricing'!$B$12 -> 200.89993 | C6: =(Assumptions!$B$87+Assumptions!$B$88+Assumptions!$B$89+Assumptions!$B$90+3000)/'B2B Model'!$B$15 -> 13.05924
A7: + $5,000 founder draw | B7: =(Assumptions!$B$87+Assumptions!$B$88+Assumptions!$B$89+Assumptions!$B$90+5000)/'B2C Pricing'!$B$12 -> 327.65067 | C7: =(Assumptions!$B$87+Assumptions!$B$88+Assumptions!$B$89+Assumptions!$B$90+5000)/'B2B Model'!$B$15 -> 21.298509
A9: Per-unit gross profit used:
A10: US B2C Pro contribution / mo | B10: ='B2C Pricing'!$B$12 -> 15.779
A11: B2B 10-seat account GP / mo | B11: ='B2B Model'!$B$15 -> 242.74

Sheet INR View
A1: INR VIEW · every headline number in $ and ₹
A2: ₹ = $ × FX (86, editable in Assumptions). India list prices (₹699 / ₹999) are set locally, not FX-converted from the US price.
A4: Metric | B4: USD | C4: INR (₹)
A5: Cost to serve, paid user (loaded) | B5: ='Cost to Serve'!$C$13 -> 3.221 | C5: =B5*Assumptions!$B$69 -> 277.006
A6: of which is AI | B6: ='Cost to Serve'!$C$7 -> 1.62 | C6: =B6*Assumptions!$B$69 -> 139.32
A7: US Pro, you keep after fees | B7: ='B2C Pricing'!$B$10 -> 19 | C7: =B7*Assumptions!$B$69 -> 1634
A8: US Pro, profit per user | B8: ='B2C Pricing'!$B$12 -> 15.779 | C8: =B8*Assumptions!$B$69 -> 1356.994
A9: UK Pro, you keep after VAT + fees | B9: ='B2C Pricing'!$C$10 -> 15.875 | C9: =B9*Assumptions!$B$69 -> 1365.25
A10: India Pro, you keep after GST + fees | B10: ='B2C Pricing'!$D$10 -> 6.8880568 | C10: =B10*Assumptions!$B$69 -> 592.37288
A11: India Pro, profit per user | B11: ='B2C Pricing'!$D$12 -> 3.6670568 | C11: =B11*Assumptions!$B$69 -> 315.36688
A12: B2B 10-seat account, monthly | B12: ='B2B Model'!$B$8 -> 290 | C12: =B12*Assumptions!$B$69 -> 24940
A13: B2B 10-seat account, lifetime value | B13: ='B2B Model'!$B$18 -> 9709.6 | C13: =B13*Assumptions!$B$69 -> 835025.6
A14: B2B 50-seat account, lifetime value | B14: ='B2B Model'!$C$18 -> 45812 | C14: =B14*Assumptions!$B$69 -> 3939832
A15: P&L 1,000 signups, monthly profit | B15: ='P&L Scenarios'!$C$22 -> 823.31 | C15: =B15*Assumptions!$B$69 -> 70804.66
A16: P&L 10,000 signups, annual revenue | B16: ='P&L Scenarios'!$D$14 -> 189000 | C16: =B16*Assumptions!$B$69 -> 16254000
A17: P&L 10,000 signups, monthly profit | B17: ='P&L Scenarios'!$D$22 -> 9963.1 | C17: =B17*Assumptions!$B$69 -> 856826.6
A18: Monthly burn ($0 salary) | B18: =Runway!$B$9 -> 170 | C18: =B18*Assumptions!$B$69 -> 14620
A19: Default-alive MRR ($0 salary) | B19: =Runway!$B$22 -> 226.66667 | C19: =B19*Assumptions!$B$69 -> 19493.333
